2018-09-12 14:45:55,225 ERROR: Exception on /user/jochik [GET] [in C:\Continuum\anaconda3\lib\site-packages\flask\app.py:1761]
Traceback (most recent call last):
  File "C:\Continuum\anaconda3\lib\site-packages\flask\app.py", line 2292, in wsgi_app
    response = self.full_dispatch_request()
  File "C:\Continuum\anaconda3\lib\site-packages\flask\app.py", line 1815, in full_dispatch_request
    rv = self.handle_user_exception(e)
  File "C:\Continuum\anaconda3\lib\site-packages\flask\app.py", line 1718, in handle_user_exception
    reraise(exc_type, exc_value, tb)
  File "C:\Continuum\anaconda3\lib\site-packages\flask\_compat.py", line 35, in reraise
    raise value
  File "C:\Continuum\anaconda3\lib\site-packages\flask\app.py", line 1813, in full_dispatch_request
    rv = self.dispatch_request()
  File "C:\Continuum\anaconda3\lib\site-packages\flask\app.py", line 1799, in dispatch_request
    return self.view_functions[rule.endpoint](**req.view_args)
  File "C:\Continuum\anaconda3\lib\site-packages\flask_login\utils.py", line 261, in decorated_view
    return func(*args, **kwargs)
  File "C:\Users\chikjo\Documents\Python_Projects\flask_tutorial\app\routes.py", line 106, in user
    next_url=next_url, prev_url=prev_url)
  File "C:\Continuum\anaconda3\lib\site-packages\flask\templating.py", line 134, in render_template
    return _render(ctx.app.jinja_env.get_or_select_template(template_name_or_list),
  File "C:\Continuum\anaconda3\lib\site-packages\jinja2\environment.py", line 869, in get_or_select_template
    return self.get_template(template_name_or_list, parent, globals)
  File "C:\Continuum\anaconda3\lib\site-packages\jinja2\environment.py", line 830, in get_template
    return self._load_template(name, self.make_globals(globals))
  File "C:\Continuum\anaconda3\lib\site-packages\jinja2\environment.py", line 804, in _load_template
    template = self.loader.load(self, name, globals)
  File "C:\Continuum\anaconda3\lib\site-packages\jinja2\loaders.py", line 125, in load
    code = environment.compile(source, name, filename)
  File "C:\Continuum\anaconda3\lib\site-packages\jinja2\environment.py", line 591, in compile
    self.handle_exception(exc_info, source_hint=source_hint)
  File "C:\Continuum\anaconda3\lib\site-packages\jinja2\environment.py", line 780, in handle_exception
    reraise(exc_type, exc_value, tb)
  File "C:\Continuum\anaconda3\lib\site-packages\jinja2\_compat.py", line 37, in reraise
    raise value.with_traceback(tb)
  File "C:\Users\chikjo\Documents\Python_Projects\flask_tutorial\app\templates\user.html", line 29, in template
    {% endif %}
  File "C:\Continuum\anaconda3\lib\site-packages\jinja2\environment.py", line 497, in _parse
    return Parser(self, source, name, encode_filename(filename)).parse()
  File "C:\Continuum\anaconda3\lib\site-packages\jinja2\parser.py", line 901, in parse
    result = nodes.Template(self.subparse(), lineno=1)
  File "C:\Continuum\anaconda3\lib\site-packages\jinja2\parser.py", line 883, in subparse
    rv = self.parse_statement()
  File "C:\Continuum\anaconda3\lib\site-packages\jinja2\parser.py", line 130, in parse_statement
    return getattr(self, 'parse_' + self.stream.current.value)()
  File "C:\Continuum\anaconda3\lib\site-packages\jinja2\parser.py", line 268, in parse_block
    node.body = self.parse_statements(('name:endblock',), drop_needle=True)
  File "C:\Continuum\anaconda3\lib\site-packages\jinja2\parser.py", line 165, in parse_statements
    result = self.subparse(end_tokens)
  File "C:\Continuum\anaconda3\lib\site-packages\jinja2\parser.py", line 883, in subparse
    rv = self.parse_statement()
  File "C:\Continuum\anaconda3\lib\site-packages\jinja2\parser.py", line 144, in parse_statement
    self.fail_unknown_tag(token.value, token.lineno)
  File "C:\Continuum\anaconda3\lib\site-packages\jinja2\parser.py", line 97, in fail_unknown_tag
    return self._fail_ut_eof(name, self._end_token_stack, lineno)
  File "C:\Continuum\anaconda3\lib\site-packages\jinja2\parser.py", line 90, in _fail_ut_eof
    self.fail(' '.join(message), lineno)
  File "C:\Continuum\anaconda3\lib\site-packages\jinja2\parser.py", line 59, in fail
    raise exc(msg, lineno, self.name, self.filename)
jinja2.exceptions.TemplateSyntaxError: Encountered unknown tag 'endif'. Jinja was looking for the following tags: 'endblock'. The innermost block that needs to be closed is 'block'.
2018-09-12 14:47:33,680 INFO: Microblog startup [in C:\Users\chikjo\Documents\Python_Projects\flask_tutorial\app\__init__.py:52]
2018-09-12 14:48:11,883 INFO: Microblog startup [in C:\Users\chikjo\Documents\Python_Projects\flask_tutorial\app\__init__.py:52]
2018-09-12 14:52:21,597 INFO: Microblog startup [in C:\Users\chikjo\Documents\Python_Projects\flask_tutorial\app\__init__.py:52]
2018-09-12 14:55:07,177 INFO: Microblog startup [in C:\Users\chikjo\Documents\Python_Projects\flask_tutorial\app\__init__.py:52]
2018-09-12 14:55:13,290 ERROR: Exception on /explore [GET] [in C:\Continuum\anaconda3\lib\site-packages\flask\app.py:1761]
Traceback (most recent call last):
  File "C:\Continuum\anaconda3\lib\site-packages\flask\app.py", line 2292, in wsgi_app
    response = self.full_dispatch_request()
  File "C:\Continuum\anaconda3\lib\site-packages\flask\app.py", line 1815, in full_dispatch_request
    rv = self.handle_user_exception(e)
  File "C:\Continuum\anaconda3\lib\site-packages\flask\app.py", line 1718, in handle_user_exception
    reraise(exc_type, exc_value, tb)
  File "C:\Continuum\anaconda3\lib\site-packages\flask\_compat.py", line 35, in reraise
    raise value
  File "C:\Continuum\anaconda3\lib\site-packages\flask\app.py", line 1813, in full_dispatch_request
    rv = self.dispatch_request()
  File "C:\Continuum\anaconda3\lib\site-packages\flask\app.py", line 1799, in dispatch_request
    return self.view_functions[rule.endpoint](**req.view_args)
  File "C:\Continuum\anaconda3\lib\site-packages\flask_login\utils.py", line 261, in decorated_view
    return func(*args, **kwargs)
  File "C:\Users\chikjo\Documents\Python_Projects\flask_tutorial\app\routes.py", line 90, in explore
    next_url=next_url, prev_url=prev_url)
NameError: name 'next_url' is not defined
2018-09-12 14:56:16,419 INFO: Microblog startup [in C:\Users\chikjo\Documents\Python_Projects\flask_tutorial\app\__init__.py:52]
2018-09-12 14:58:26,073 INFO: Microblog startup [in C:\Users\chikjo\Documents\Python_Projects\flask_tutorial\app\__init__.py:52]
2018-09-12 14:59:48,050 INFO: Microblog startup [in C:\Users\chikjo\Documents\Python_Projects\flask_tutorial\app\__init__.py:52]
2018-09-12 14:59:49,261 ERROR: Exception on /edit_profile [GET] [in C:\Continuum\anaconda3\lib\site-packages\flask\app.py:1761]
Traceback (most recent call last):
  File "C:\Continuum\anaconda3\lib\site-packages\flask\app.py", line 2292, in wsgi_app
    response = self.full_dispatch_request()
  File "C:\Continuum\anaconda3\lib\site-packages\flask\app.py", line 1815, in full_dispatch_request
    rv = self.handle_user_exception(e)
  File "C:\Continuum\anaconda3\lib\site-packages\flask\app.py", line 1718, in handle_user_exception
    reraise(exc_type, exc_value, tb)
  File "C:\Continuum\anaconda3\lib\site-packages\flask\_compat.py", line 35, in reraise
    raise value
  File "C:\Continuum\anaconda3\lib\site-packages\flask\app.py", line 1813, in full_dispatch_request
    rv = self.dispatch_request()
  File "C:\Continuum\anaconda3\lib\site-packages\flask\app.py", line 1799, in dispatch_request
    return self.view_functions[rule.endpoint](**req.view_args)
  File "C:\Continuum\anaconda3\lib\site-packages\flask_login\utils.py", line 261, in decorated_view
    return func(*args, **kwargs)
  File "C:\Users\chikjo\Documents\Python_Projects\flask_tutorial\app\routes.py", line 140, in edit_profile
    return render_template('edit_profile.html', title='Edit Profile', form=form)
  File "C:\Continuum\anaconda3\lib\site-packages\flask\templating.py", line 135, in render_template
    context, ctx.app)
  File "C:\Continuum\anaconda3\lib\site-packages\flask\templating.py", line 117, in _render
    rv = template.render(context)
  File "C:\Continuum\anaconda3\lib\site-packages\jinja2\environment.py", line 1008, in render
    return self.environment.handle_exception(exc_info, True)
  File "C:\Continuum\anaconda3\lib\site-packages\jinja2\environment.py", line 780, in handle_exception
    reraise(exc_type, exc_value, tb)
  File "C:\Continuum\anaconda3\lib\site-packages\jinja2\_compat.py", line 37, in reraise
    raise value.with_traceback(tb)
  File "C:\Users\chikjo\Documents\Python_Projects\flask_tutorial\app\templates\edit_profile.html", line 1, in top-level template code
    {% extends "base.html" %}
  File "C:\Users\chikjo\Documents\Python_Projects\flask_tutorial\app\templates\base.html", line 75, in top-level template code
    {% block content %}
  File "C:\Users\chikjo\Documents\Python_Projects\flask_tutorial\app\templates\edit_profile.html", line 7, in block "content"
    {{ wtf.quick_form(form) }}
  File "C:\Continuum\anaconda3\lib\site-packages\jinja2\environment.py", line 430, in getattr
    return getattr(obj, attribute)
jinja2.exceptions.UndefinedError: 'wtf' is undefined
2018-09-12 15:00:15,639 INFO: Microblog startup [in C:\Users\chikjo\Documents\Python_Projects\flask_tutorial\app\__init__.py:52]
